Workbook

Sheet Setup
A1: BUSINESS SETUP
A2: Enter your details once - they will appear on all estimates and quotes.
A4: Business Name:
A5: ABN:
A6: Builder Licence:
A7: Address:
A8: Phone:
A9: Email:
A11: DEFAULT RATES
A12: Set your standard rates here. You can override these on individual estimates.
A14: Default Hourly Rate: | B14: 85
A15: Default Daily Rate: | B15: 680
A16: Default Markup on Cost (%): | B16: 0.2
A17: Default Contingency (%): | B17: 0.05
A18: GST Rate: | B18: 0.1
A20: TRADE CATEGORIES
A21: Standard Australian trade categories. Customise as needed.
A23: 1 | B23: Preliminaries & Site Setup
A24: 2 | B24: Demolition & Site Clearance
A25: 3 | B25: Earthworks & Excavation
A26: 4 | B26: Concrete & Footings
A27: 5 | B27: Structural Steel
A28: 6 | B28: Framing & Carpentry
A29: 7 | B29: Roofing & Guttering
A30: 8 | B30: External Cladding
A31: 9 | B31: Windows & Glazing
A32: 10 | B32: External Doors
A33: 11 | B33: Internal Walls & Linings
A34: 12 | B34: Internal Doors & Hardware
... A49: 27 | B49: Other

Sheet Estimate
A1: PROJECT ESTIMATE
A3: Project Name: | F3: Date:
A4: Project Address: | F4: Estimate No:
A5: Client Name: | F5: Version: | G5: 1.0
A7: LABOUR
A8: Trade/Task | B8: Description | C8: Qty | D8: Unit | E8: Rate ($) | F8: Amount ($) | G8: Notes
E9: =Setup!B14 | F9: =IF(OR(C9="",E9=""),"",C9*E9)
E10: =Setup!B14 | F10: =IF(OR(C10="",E10=""),"",C10*E10)
E11: =Setup!B14 | F11: =IF(OR(C11="",E11=""),"",C11*E11)
E12: =Setup!B14 | F12: =IF(OR(C12="",E12=""),"",C12*E12)
E13: =Setup!B14 | F13: =IF(OR(C13="",E13=""),"",C13*E13)
E14: =Setup!B14 | F14: =IF(OR(C14="",E14=""),"",C14*E14)
E15: =Setup!B14 | F15: =IF(OR(C15="",E15=""),"",C15*E15)
E16: =Setup!B14 | F16: =IF(OR(C16="",E16=""),"",C16*E16)
E17: =Setup!B14 | F17: =IF(OR(C17="",E17=""),"",C17*E17)
E18: =Setup!B14 | F18: =IF(OR(C18="",E18=""),"",C18*E18)
E19: =Setup!B14 | F19: =IF(OR(C19="",E19=""),"",C19*E19)
E20: =Setup!B14 | F20: =IF(OR(C20="",E20=""),"",C20*E20)
E21: =Setup!B14 | F21: =IF(OR(C21="",E21=""),"",C21*E21)
E22: =Setup!B14 | F22: =IF(OR(C22="",E22=""),"",C22*E22)
E23: =Setup!B14 | F23: =IF(OR(C23="",E23=""),"",C23*E23)
E24: =Setup!B14 | F24: =IF(OR(C24="",E24=""),"",C24*E24)
E25: =Setup!B14 | F25: =IF(OR(C25="",E25=""),"",C25*E25)
E26: =Setup!B14 | F26: =IF(OR(C26="",E26=""),"",C26*E26)
E27: =Setup!B14 | F27: =IF(OR(C27="",E27=""),"",C27*E27)
E28: =Setup!B14 | F28: =IF(OR(C28="",E28=""),"",C28*E28)
E29: LABOUR SUBTOTAL: | F29: =SUM(F9:F28)
A31: MATERIALS
A32: Item | B32: Description | C32: Qty | D32: Unit | E32: Unit Cost ($) | F32: Amount ($) | G32: Supplier
F33: =IF(OR(C33="",E33=""),"",C33*E33)
F34: =IF(OR(C34="",E34=""),"",C34*E34)
F35: =IF(OR(C35="",E35=""),"",C35*E35)
F36: =IF(OR(C36="",E36=""),"",C36*E36)
F37: =IF(OR(C37="",E37=""),"",C37*E37)
F38: =IF(OR(C38="",E38=""),"",C38*E38)
F39: =IF(OR(C39="",E39=""),"",C39*E39)
F40: =IF(OR(C40="",E40=""),"",C40*E40)
F41: =IF(OR(C41="",E41=""),"",C41*E41)
F42: =IF(OR(C42="",E42=""),"",C42*E42)
F43: =IF(OR(C43="",E43=""),"",C43*E43)
...

Sheet Quote Output
A1: =Setup!B4
A2: =IF(Setup!B5="","","ABN: "&Setup!B5)
A3: =IF(Setup!B6="","","Licence: "&Setup!B6)
A4: =Setup!B7
A5: =IF(Setup!B8="","","Ph: "&Setup!B8&" | "&Setup!B9)
A7: QUOTATION
A9: Quote To: | B9: =Estimate!B5 | D9: Quote No: | E9: =Estimate!G4
A10: Project: | B10: =Estimate!B3 | D10: Date: | E10: =Estimate!G3
A11: Address: | B11: =Estimate!B4 | D11: Valid For: | E11: 30 days
A13: QUOTE SUMMARY
A14: Description | E14: Amount
A15: Labour | E15: =Estimate!F29*(1+Setup!B16)
A16: Materials | E16: =Estimate!F58*(1+Setup!B16)
A17: Subcontract Works | E17: =Estimate!E77*(1+Setup!B16)
A18: Contingency Allowance | E18: =Estimate!F87*(1+Setup!B16)
A20: Subtotal (excl. GST) | E20: =Estimate!F93
A21: GST (10%) | E21: =Estimate!F94
A22: TOTAL (incl. GST) | E22: =Estimate!F96
A24: TERMS & CONDITIONS
A25: 1. This quote is valid for 30 days from the date shown above.
A26: 2. Payment terms: As per contract or 50% deposit, balance on completion.
A27: 3. This quote is based on the scope discussed and excludes variations.
A28: 4. Variations to scope will be quoted separately before work commences.
A29: 5. Work carried out per Australian Standards and BCA requirements.
A32: ACCEPTANCE
A34: I/We accept this quotation and authorise the work to proceed.
A36: Client Signature: _______________________________ Date: _______________

Sheet Instructions
A1: HOW TO USE THIS ESTIMATE WORKBOOK
A3: QUICK START
A4: 1. Setup | B4: Enter your business details and default rates in the Setup sheet.
A5: 2. Project Info | B5: Fill in project name, address, client, date and estimate number.
A6: 3. Labour | B6: Enter tasks with quantity, unit (hrs/days), and rate. Amount auto-calculates.
A7: 4. Materials | B7: Enter items with quantity, unit, and unit cost. Amount auto-calculates.
A8: 5. Subbies | B8: Enter subcontractor quotes with trade, name, and amount.
A9: 6. Review | B9: Check the Summary section. Contingency and margin use your Setup rates.
A10: 7. Quote | B10: The Quote Output sheet shows a client-ready version with margin hidden.
A12: CELL COLOURS
A13: Yellow | B13: Input cells - enter your data here
A14: Green | B14: Calculated fields - do not edit (formulas will break)
A15: Grey | B15: Labels - do not edit
A17: UNITS | B17: hrs=hours, days=days, ea=each, m=metres, m2=square metres, m3=cubic metres
B18: lm=lineal metres, kg=kilograms, t=tonnes, lot=job lot, allow=allowance
A20: TIPS
B21: - Save a copy for each new estimate (File > Save As)
B22: - The Quote Output hides your margin from clients
B23: - Adjust contingency and margin % in Setup sheet
B24: - Labour rate defaults from Setup but can be overridden per row
